<?xml version="1.0"?>
<robot name="simple_drone">
    <!-- Link representing the body of the drone -->
    <link name="base_link">
        <visual>
            <geometry>
                <cylinder radius="0.2" length="0.05"/>
            </geometry>
            <material name="green"/>
        </visual>
        <collision>
            <geometry>
                <cylinder radius="0.2" length="0.05"/>
            </geometry>
        </collision>
    </link>

    <!-- 4 Thrusters attached to the drone -->
    <link name="thruster1">
        <visual>
            <geometry>
                <cylinder radius="0.05" length="0.1"/>
            </geometry>
            <material name="yellow"/>
        </visual>
        <collision>
            <geometry>
                <cylinder radius="0.05" length="0.1"/>
            </geometry>
        </collision>
    </link>

    <link name="thruster2">
        <visual>
            <geometry>
                <cylinder radius="0.05" length="0.1"/>
            </geometry>
            <material name="yellow"/>
        </visual>
        <collision>
            <geometry>
                <cylinder radius="0.05" length="0.1"/>
            </geometry>
        </collision>
    </link>

    <link name="thruster3">
        <visual>
            <geometry>
                <cylinder radius="0.05" length="0.1"/>
            </geometry>
            <material name="yellow"/>
        </visual>
        <collision>
            <geometry>
                <cylinder radius="0.05" length="0.1"/>
            </geometry>
        </collision>
    </link>

    <link name="thruster4">
        <visual>
            <geometry>
                <cylinder radius="0.05" length="0.1"/>
            </geometry>
            <material name="yellow"/>
        </visual>
        <collision>
            <geometry>
                <cylinder radius="0.05" length="0.1"/>
            </geometry>
        </collision>
    </link>

    <!-- Joints connecting the base to the thrusters -->
    <joint name="base_to_thruster1" type="revolute">
        <parent link="base_link"/>
        <child link="thruster1"/>
        <origin xyz="0.2 0 0.1" rpy="0 0 0"/>
        <axis xyz="0 0 1"/>
        <limit effort="100" lower="0" upper="3.1416" velocity="1"/>
    </joint>

    <joint name="base_to_thruster2" type="revolute">
        <parent link="base_link"/>
        <child link="thruster2"/>
        <origin xyz="-0.2 0 0.1" rpy="0 0 0"/>
        <axis xyz="0 0 1"/>
        <limit effort="100" lower="0" upper="3.1416" velocity="1"/>
    </joint>

    <joint name="base_to_thruster3" type="revolute">
        <parent link="base_link"/>
        <child link="thruster3"/>
        <origin xyz="0.2 0 -0.1" rpy="0 0 0"/>
        <axis xyz="0 0 1"/>
        <limit effort="100" lower="0" upper="3.1416" velocity="1"/>
    </joint>

    <joint name="base_to_thruster4" type="revolute">
        <parent link="base_link"/>
        <child link="thruster4"/>
        <origin xyz="-0.2 0 -0.1" rpy="0 0 0"/>
        <axis xyz="0 0 1"/>
        <limit effort="100" lower="0" upper="3.1416" velocity="1"/>
    </joint>

    <!-- Additional links and joints for the drone's components can be added here -->
</robot>
